<?xml version="1.0" ?>
<!-- =================================================================================== -->
<!-- |    This document was autogenerated by xacro from /home/jacob/Documents/TangerineModel.urdf.xacro | -->
<!-- |    EDITING THIS FILE BY HAND IS NOT RECOMMENDED                                 | -->
<!-- =================================================================================== -->
<robot name="tangerige" xmlns:xacro="http://www.ros.org/wiki/xacro">
  <!-- .......................MACROS.................... -->
  <!-- ....................... END MACROS.................... -->
  <!-- ................BASE................. -->
  <link name="root_frame_dummy">
    <visual>
      <geometry>
	<box size="0 0 0"/>
      </geometry>
    </visual>
    <inertial>
      <mass value=".001"/>
      <inertia ixx="1.0" ixy="0.0" ixz="0.0" iyy="1.0" iyz="0.0" izz="1.0"/>
    </inertial>
  </link>
  <joint name="root_frame_to_base_torso" type="planar">
    <parent link="root_frame_dummy"/>
    <child link="base_link_robot"/>
    <origin xyz="0 0 0"/>
  </joint>
  <link name="base_link_robot">
    <visual>
      <geometry>
        <box size="0.51 0.51 0.2"/>
      </geometry>
      <material name="orange">
        <color rgba=".8 .2 0 1"/>
      </material>
    </visual>
    <collision>
      <geometry>
        <cylinder length="0.2" radius="0.31"/>
      </geometry>
    </collision>
    <inertial>
      <mass value="10"/>
      <inertia ixx="1.0" ixy="0.0" ixz="0.0" iyy="1.0" iyz="0.0" izz="1.0"/>
    </inertial>
    <origin xyz="0 0 -.1"/>
    <dynamics damping="0.7" friction="1000.0"/>
  </link>
  <gazebo reference="base_link">
    <material>Gazebo/Red</material>
  </gazebo>
  <joint name="base_link_to_torso" type="fixed">
    <axis xyz="1 0 0"/>
    <limit effort="1000.0" lower="0" upper="0" velocity="0"/>
    <parent link="base_link_robot"/>
    <child link="base_torso"/>
    <origin xyz="-0.093 0 0.3"/>
  </joint>
  <link name="base_torso">
    <visual>
      <geometry>
        <box size="0.176 0.15 0.4"/>
      </geometry>
      <material name="grey">
        <color rgba="0.5 0.5 0.5 1"/>
      </material>
      <origin rpy="0 0 1.57075"/>
    </visual>
    <collision>
      <geometry>
        <cylinder length="0.55" radius="0.13"/>
      </geometry>
    </collision>
    <inertial>
      <mass value="6"/>
      <inertia ixx="1.0" ixy="0.0" ixz="0.0" iyy="1.0" iyz="0.0" izz="1.0"/>
    </inertial>
    <dynamics damping="0.7" friction="1000.0"/>
  </link>
  <gazebo reference="base_torso">
    <material>Gazebo/Red</material>
  </gazebo>
  <link name="upper_base_torso">
    <visual>
      <geometry>
        <box size="0.176 0.15 0.15"/>
      </geometry>
      <material name="grey"/>
    </visual>
    <collision>
      <geometry>
        <cylinder length="0.55" radius="0.13"/>
      </geometry>
    </collision>
    <inertial>
      <mass value="6"/>
      <inertia ixx="1.0" ixy="0.0" ixz="0.0" iyy="1.0" iyz="0.0" izz="1.0"/>
    </inertial>
    <dynamics damping="0.7" friction="1000.0"/>
  </link>
  <gazebo reference="upper_base_torso">
    <material>Gazebo/Gray</material>
  </gazebo>
  <joint name="torso_to_upper_base" type="revolute">
    <axis xyz="1 0 0"/>
    <limit effort="1000.0" lower="0" upper="0" velocity="0"/>
    <parent link="base_torso"/>
    <child link="upper_base_torso"/>
    <origin rpy="0 0 -1.57075" xyz="0 0 0.275"/>
  </joint>
  <link name="superior_link">
    <visual>
      <geometry>
        <box size="0.305 0.360 0.4"/>
      </geometry>
      <material name="black">
        <color rgba="0 0 0 1"/>
      </material>
    </visual>
    <collision>
      <geometry>
        <cylinder length="0.4" radius="0.22"/>
      </geometry>
    </collision>
    <inertial>
      <mass value="8"/>
      <inertia ixx="1.0" ixy="0.0" ixz="0.0" iyy="1.0" iyz="0.0" izz="1.0"/>
    </inertial>
    <dynamics damping="0.7" friction="1000.0"/>
  </link>
  <gazebo reference="superior_link">
    <material>Gazebo/Black</material>
  </gazebo>
  <joint name="upper_base_to_superior_link" type="revolute">
    <axis xyz="1 0 0"/>
    <limit effort="1000.0" lower="0" upper="0" velocity="0"/>
    <parent link="upper_base_torso"/>
    <child link="superior_link"/>
    <origin xyz="0 0 0.275"/>
  </joint>
  <link name="skeleton/openni_depth_frame">
    <visual>
      <geometry>
        <box size="0.04 0.18 0.04"/>
      </geometry>
      <material name="grey">
        <color rgba="0 0 0 0.5"/>
      </material>
    </visual>
    <collision>
      <geometry>
        <cylinder length="0.01" radius="0.01"/>
      </geometry>
    </collision>
    <inertial>
      <mass value="0.01"/>
      <inertia ixx="1.0" ixy="0.0" ixz="0.0" iyy="1.0" iyz="0.0" izz="1.0"/>
    </inertial>
    <dynamics damping="0.7" friction="1000.0"/>
  </link>
  <joint name="superior_link_to_openni_depth_frame" type="revolute">
    <axis xyz="1 0 0"/>
    <limit effort="1000.0" lower="0" upper="0" velocity="0"/>
    <parent link="superior_link"/>
    <child link="skeleton/openni_depth_frame"/>
    <origin rpy="0 0 1.57075" xyz="0 0.1325 0.22"/>
  </joint>
  <!-- ................END BASE................. -->
  <!-- ................HEAD................. -->
  <link name="neck_link">
    <visual>
      <geometry>
        <box size="0.05 0.08 0.07"/>
      </geometry>
      <material name="grey"/>
    </visual>
    <collision>
      <geometry>
        <cylinder length="0.07" radius="0.036"/>
      </geometry>
    </collision>
    <inertial>
      <mass value="0.5"/>
      <inertia ixx="1.0" ixy="0.0" ixz="0.0" iyy="1.0" iyz="0.0" izz="1.0"/>
    </inertial>
    <dynamics damping="0.7" friction="1000.0"/>
  </link>
  <gazebo reference="neck_link">
    <material>Gazebo/Red</material>
  </gazebo>
  <joint name="superior_to_neck_link" type="revolute">
    <axis xyz="1 0 0"/>
    <limit effort="1000.0" lower="0" upper="0" velocity="0"/>
    <parent link="superior_link"/>
    <child link="neck_link"/>
    <origin xyz="0 0 0.235"/>
  </joint>
  <link name="neck_z_revolute">
    <collision>
      <geometry>
        <cylinder length="0.01" radius="0.01"/>
      </geometry>
    </collision>
    <inertial>
      <mass value="0.01"/>
      <inertia ixx="1.0" ixy="0.0" ixz="0.0" iyy="1.0" iyz="0.0" izz="1.0"/>
    </inertial>
    <dynamics damping="0.7" friction="1000.0"/>
  </link>
  <joint name="neck_to_z_revolute" type="revolute">
    <axis xyz="0 0 1"/>
    <limit effort="1000.0" lower="-0.7853" upper="0.7853" velocity="5"/>
    <parent link="neck_link"/>
    <child link="neck_z_revolute"/>
  </joint>
  <link name="neck_x_revolute">
    <collision>
      <geometry>
        <cylinder length="0.01" radius="0.01"/>
      </geometry>
    </collision>
    <inertial>
      <mass value="0.01"/>
      <inertia ixx="1.0" ixy="0.0" ixz="0.0" iyy="1.0" iyz="0.0" izz="1.0"/>
    </inertial>
    <dynamics damping="0.7" friction="1000.0"/>
  </link>
  <joint name="z_revolute_to_x_revolute" type="revolute">
    <axis xyz="1 0 0"/>
    <limit effort="1000.0" lower="-0.3926" upper="0.3926" velocity="5"/>
    <parent link="neck_z_revolute"/>
    <child link="neck_x_revolute"/>
  </joint>
  <link name="head">
    <visual>
      <geometry>
        <box size="0.222 0.065 0.18"/>
      </geometry>
      <material name="orange"/>
    </visual>
    <collision>
      <geometry>
        <cylinder length="0.18" radius="0.16"/>
      </geometry>
    </collision>
    <inertial>
      <mass value="4"/>
      <inertia ixx="1.0" ixy="0.0" ixz="0.0" iyy="1.0" iyz="0.0" izz="1.0"/>
    </inertial>
    <dynamics damping="0.7" friction="1000.0"/>
  </link>
  <gazebo reference="head">
    <material>Gazebo/Red</material>
  </gazebo>
  <joint name="revolute_head" type="revolute">
    <axis xyz="1 0 0"/>
    <limit effort="1000.0" lower="0" upper="0" velocity="0"/>
    <parent link="neck_x_revolute"/>
    <child link="head"/>
    <origin xyz="0 0 0.125"/>
  </joint>
  <link name="right_eye">
    <visual>
      <geometry>
        <cylinder length="0.015" radius="0.015"/>
      </geometry>
      <material name="black"/>
      <origin rpy="-1.57075 0 0"/>
    </visual>
    <collision>
      <geometry>
        <cylinder length="0.03" radius="0.01"/>
      </geometry>
    </collision>
    <inertial>
      <mass value="0.2"/>
      <inertia ixx="1.0" ixy="0.0" ixz="0.0" iyy="1.0" iyz="0.0" izz="1.0"/>
    </inertial>
    <dynamics damping="0.7" friction="1000.0"/>
  </link>
  <joint name="right_eye_to_head" type="revolute">
    <axis xyz="1 0 0"/>
    <limit effort="1000.0" lower="0" upper="0" velocity="0"/>
    <parent link="head"/>
    <child link="right_eye"/>
    <origin xyz="0.05 0.03 0.03"/>
  </joint>
  <link name="left_eye">
    <visual>
      <geometry>
        <cylinder length="0.015" radius="0.015"/>
      </geometry>
      <material name="black"/>
      <origin rpy="-1.57075 0 0"/>
    </visual>
    <collision>
      <geometry>
        <cylinder length="0.03" radius="0.01"/>
      </geometry>
    </collision>
    <inertial>
      <mass value="0.2"/>
      <inertia ixx="1.0" ixy="0.0" ixz="0.0" iyy="1.0" iyz="0.0" izz="1.0"/>
    </inertial>
    <dynamics damping="0.7" friction="1000.0"/>
  </link>
  <joint name="left_eye_to_head" type="revolute">
    <axis xyz="1 0 0"/>
    <limit effort="1000.0" lower="0" upper="0" velocity="0"/>
    <parent link="head"/>
    <child link="left_eye"/>
    <origin xyz="-0.05 0.03 0.03"/>
  </joint>
  <!-- ................END HEAD................. -->
  <!-- ................RIGHT ARM................. -->
  <link name="right_shoulder_link">
    <visual>
      <geometry>
        <box size="0.07 0.14 0.17"/>
      </geometry>
      <material name="orange"/>
    </visual>
    <collision>
      <geometry>
        <cylinder length="0.23" radius="0.13"/>
      </geometry>
    </collision>
    <inertial>
      <mass value="2"/>
      <inertia ixx="1.0" ixy="0.0" ixz="0.0" iyy="1.0" iyz="0.0" izz="1.0"/>
    </inertial>
    <dynamics damping="0.7" friction="1000.0"/>
  </link>
  <gazebo reference="right_shoulder_link">
    <material>Gazebo/Gray</material>
  </gazebo>
  <joint name="superior_link_to_right_shoulder_link" type="revolute">
    <axis xyz="1 0 0"/>
    <limit effort="1000.0" lower="-0.785375" upper="1.57075" velocity="5"/>
    <parent link="superior_link"/>
    <child link="right_shoulder_link"/>
    <origin xyz="0.1875 0 0.07"/>
  </joint>
  <link name="right_shoulder">
    <visual>
      <geometry>
        <box size="0.10 0.14 0.17"/>
      </geometry>
      <material name="grey"/>
    </visual>
    <collision>
      <geometry>
        <cylinder length="0.23" radius="0.13"/>
      </geometry>
    </collision>
    <inertial>
      <mass value="2"/>
      <inertia ixx="1.0" ixy="0.0" ixz="0.0" iyy="1.0" iyz="0.0" izz="1.0"/>
    </inertial>
    <dynamics damping="0.7" friction="1000.0"/>
  </link>
  <gazebo reference="right_shoulder">
    <material>Gazebo/Gray</material>
  </gazebo>
  <joint name="right_shoulder_x_revolute" type="revolute">
    <axis xyz="1 0 0"/>
    <limit effort="1000.0" lower="-0.785375" upper="1.57075" velocity="5"/>
    <parent link="superior_link"/>
    <child link="right_shoulder"/>
    <origin xyz="0.2725 0 0.12"/>
  </joint>
  <link name="upper_right_arm_z_revolute">
    <collision>
      <geometry>
        <cylinder length="0.01" radius="0.01"/>
      </geometry>
    </collision>
    <inertial>
      <mass value="0.01"/>
      <inertia ixx="1.0" ixy="0.0" ixz="0.0" iyy="1.0" iyz="0.0" izz="1.0"/>
    </inertial>
    <dynamics damping="0.7" friction="1000.0"/>
  </link>
  <joint name="upper_right_arm_z_revolute" type="revolute">
    <axis xyz="0 0 1"/>
    <limit effort="1000.0" lower="-0.7" upper="0.7" velocity="5"/>
    <parent link="right_shoulder"/>
    <child link="upper_right_arm_z_revolute"/>
    <origin xyz="0 0 0"/>
  </joint>
  <link name="upper_right_arm_y_revolute">
    <collision>
      <geometry>
        <cylinder length="0.01" radius="0.01"/>
      </geometry>
    </collision>
    <inertial>
      <mass value="0.01"/>
      <inertia ixx="1.0" ixy="0.0" ixz="0.0" iyy="1.0" iyz="0.0" izz="1.0"/>
    </inertial>
    <dynamics damping="0.7" friction="1000.0"/>
  </link>
  <joint name="upper_right_arm_y_revolute" type="revolute">
    <axis xyz="0 1 0"/>
    <limit effort="1000.0" lower="-.4" upper="0" velocity="5"/>
    <parent link="upper_right_arm_z_revolute"/>
    <child link="upper_right_arm_y_revolute"/>
    <origin xyz="0 0 0"/>
  </joint>
  <link name="upper_right_arm">
    <visual>
      <geometry>
        <box size="0.065 0.08 0.17"/>
      </geometry>
      <material name="grey"/>
    </visual>
    <collision>
      <geometry>
        <cylinder length="0.17" radius="0.046"/>
      </geometry>
    </collision>
    <inertial>
      <mass value="3"/>
      <inertia ixx="1.0" ixy="0.0" ixz="0.0" iyy="1.0" iyz="0.0" izz="1.0"/>
    </inertial>
    <dynamics damping="0.7" friction="1000.0"/>
  </link>
  <gazebo reference="upper_right_arm">
    <material>Gazebo/Gray</material>
  </gazebo>
  <joint name="shoulder_to_upper_right_arm" type="fixed">
    <parent link="upper_right_arm_y_revolute"/>
    <child link="upper_right_arm"/>
    <origin xyz="0 0 -0.17"/>
  </joint>
  <joint name="upper_to_lower_right_joint" type="revolute">
    <axis xyz="1 0 0"/>
    <limit effort="1000.0" lower="0" upper="1.5706" velocity="5"/>
    <parent link="upper_right_arm"/>
    <child link="lower_right_arm_y_revolute"/>
    <origin xyz="0 0 -.085"/>
  </joint>
  <link name="lower_right_arm_y_revolute">
    <collision>
      <geometry>
        <cylinder length="0.01" radius="0.01"/>
      </geometry>
    </collision>
    <inertial>
      <mass value="0.01"/>
      <inertia ixx="1.0" ixy="0.0" ixz="0.0" iyy="1.0" iyz="0.0" izz="1.0"/>
    </inertial>
    <origin xyz="0 0 0"/>
    <dynamics damping="0.7" friction="1000.0"/>
  </link>
  <joint name="lower_right_joint_to_lower_arm" type="fixed">
    <parent link="lower_right_arm_y_revolute"/>
    <child link="lower_right_arm"/>
    <origin xyz="0 0 -.105"/>
  </joint>
  <link name="lower_right_arm">
    <visual>
      <geometry>
        <box size="0.065 0.08 0.21"/>
      </geometry>
      <material name="grey"/>
    </visual>
    <collision>
      <geometry>
        <cylinder length="0.21" radius="0.046"/>
      </geometry>
    </collision>
    <inertial>
      <mass value="0.5"/>
      <inertia ixx="1.0" ixy="0.0" ixz="0.0" iyy="1.0" iyz="0.0" izz="1.0"/>
    </inertial>
    <dynamics damping="0.7" friction="1000.0"/>
  </link>
  <gazebo reference="lower_right_arm">
    <material>Gazebo/Gray</material>
  </gazebo>
  <link name="wrist_right_arm_z_revolute">
    <collision>
      <geometry>
        <cylinder length="0.01" radius="0.01"/>
      </geometry>
    </collision>
    <inertial>
      <mass value="0.01"/>
      <inertia ixx="1.0" ixy="0.0" ixz="0.0" iyy="1.0" iyz="0.0" izz="1.0"/>
    </inertial>
    <dynamics damping="0.7" friction="1000.0"/>
  </link>
  <joint name="wrist_right_arm_z_revolute" type="revolute">
    <axis xyz="0 0 1"/>
    <limit effort="1000.0" lower="-2" upper="2" velocity="5"/>
    <parent link="lower_right_arm"/>
    <child link="wrist_right_arm_z_revolute"/>
  </joint>
  <link name="wrist_right_arm_x_revolute">
    <collision>
      <geometry>
        <cylinder length="0.01" radius="0.01"/>
      </geometry>
    </collision>
    <inertial>
      <mass value="0.01"/>
      <inertia ixx="1.0" ixy="0.0" ixz="0.0" iyy="1.0" iyz="0.0" izz="1.0"/>
    </inertial>
    <dynamics damping="0.7" friction="1000.0"/>
  </link>
  <joint name="wrist_right_arm_x_revolute" type="fixed">
    <parent link="wrist_right_arm_z_revolute"/>
    <child link="wrist_right_arm_x_revolute"/>
  </joint>
  <link name="wrist_right_arm">
    <visual>
      <geometry>
        <sphere radius="0.0325"/>
      </geometry>
      <material name="black"/>
    </visual>
    <collision>
      <geometry>
        <cylinder length="0.0325" radius="0.0325"/>
      </geometry>
    </collision>
    <inertial>
      <mass value="1"/>
      <inertia ixx="1.0" ixy="0.0" ixz="0.0" iyy="1.0" iyz="0.0" izz="1.0"/>
    </inertial>
    <dynamics damping="0.7" friction="1000.0"/>
  </link>
  <gazebo reference="wrist_right_arm">
    <material>Gazebo/Black</material>
  </gazebo>
  <joint name="lower_to_wrist_right_arm" type="revolute">
    <axis xyz="1 0 0"/>
    <limit effort="1000.0" lower="-1.047" upper="1.047" velocity="5"/>
    <parent link="wrist_right_arm_x_revolute"/>
    <child link="wrist_right_arm"/>
    <origin xyz="0 0 -0.105"/>
  </joint>
  <link name="finger1_right_arm">
    <visual>
      <geometry>
        <box size="0.01 0.01 0.05"/>
      </geometry>
      <origin xyz="0 0 -0.025"/>
      <material name="grey"/>
    </visual>
    <collision>
      <geometry>
        <cylinder length="0.05" radius="0.005"/>
      </geometry>
    </collision>
    <inertial>
      <mass value="0.2"/>
      <inertia ixx="1.0" ixy="0.0" ixz="0.0" iyy="1.0" iyz="0.0" izz="1.0"/>
    </inertial>
    <dynamics damping="0.7" friction="1000.0"/>
  </link>
  <gazebo reference="finger1_right_arm">
    <material>Gazebo/Gray</material>
  </gazebo>
  <joint name="wrist_to_finger1_right_arm" type="revolute">
    <axis xyz="0 1 0"/>
    <limit effort="1000.0" lower="0" upper="-0.68" velocity="5"/>
    <parent link="wrist_right_arm"/>
    <child link="finger1_right_arm"/>
    <origin rpy="0 0.3926875 0" xyz="-0.01875 0 -0.0375"/>
  </joint>
  <link name="finger2_right_arm">
    <visual>
      <geometry>
        <box size="0.01 0.03 0.05"/>
      </geometry>
      <origin xyz="0 0 -0.025"/>
      <material name="grey"/>
    </visual>
    <collision>
      <geometry>
        <cylinder length="0.05" radius="0.005"/>
      </geometry>
    </collision>
    <inertial>
      <mass value="0.2"/>
      <inertia ixx="1.0" ixy="0.0" ixz="0.0" iyy="1.0" iyz="0.0" izz="1.0"/>
    </inertial>
    <dynamics damping="0.7" friction="1000.0"/>
  </link>
  <gazebo reference="finger2_right_arm">
    <material>Gazebo/Gray</material>
  </gazebo>
  <joint name="wrist_to_finger2_right_arm" type="revolute">
    <axis xyz="0 1 0"/>
    <limit effort="1000.0" lower="0.68" upper="0" velocity="5"/>
    <parent link="wrist_right_arm"/>
    <child link="finger2_right_arm"/>
    <origin rpy="0 -0.3926875 0" xyz="0.01875 0 -0.0375"/>
  </joint>
  <!-- ................END RIGHT ARM................. -->
  <!-- ................LEFT ARM................. -->
  <link name="left_shoulder_link">
    <visual>
      <geometry>
        <box size="0.07 0.14 0.17"/>
      </geometry>
      <material name="orange"/>
    </visual>
    <collision>
      <geometry>
        <cylinder length="0.23" radius="0.13"/>
      </geometry>
    </collision>
    <inertial>
      <mass value="2"/>
      <inertia ixx="1.0" ixy="0.0" ixz="0.0" iyy="1.0" iyz="0.0" izz="1.0"/>
    </inertial>
    <dynamics damping="0.7" friction="1000.0"/>
  </link>
  <gazebo reference="left_shoulder_link">
    <material>Gazebo/Gray</material>
  </gazebo>
  <joint name="superior_link_to_left_shoulder_link" type="revolute">
    <axis xyz="1 0 0"/>
    <limit effort="1000.0" lower="-0.785375" upper="1.57075" velocity="5"/>
    <parent link="superior_link"/>
    <child link="left_shoulder_link"/>
    <origin xyz="-0.1875 0 0.07"/>
  </joint>
  <link name="left_shoulder">
    <visual>
      <geometry>
        <box size="0.10 0.14 0.17"/>
      </geometry>
      <material name="grey"/>
    </visual>
    <collision>
      <geometry>
        <cylinder length="0.23" radius="0.13"/>
      </geometry>
    </collision>
    <inertial>
      <mass value="2"/>
      <inertia ixx="1.0" ixy="0.0" ixz="0.0" iyy="1.0" iyz="0.0" izz="1.0"/>
    </inertial>
    <dynamics damping="0.7" friction="1000.0"/>
  </link>
  <gazebo reference="left_shoulder">
    <material>Gazebo/Gray</material>
  </gazebo>
  <joint name="left_shoulder_x_revolute" type="revolute">
    <axis xyz="1 0 0"/>
    <limit effort="1000.0" lower="-0.785375" upper="1.57075" velocity="5"/>
    <parent link="superior_link"/>
    <child link="left_shoulder"/>
    <origin xyz="-0.2725 0 0.12"/>
  </joint>
  <link name="upper_left_arm_z_revolute">
    <collision>
      <geometry>
        <cylinder length="0.01" radius="0.01"/>
      </geometry>
    </collision>
    <inertial>
      <mass value="0.01"/>
      <inertia ixx="1.0" ixy="0.0" ixz="0.0" iyy="1.0" iyz="0.0" izz="1.0"/>
    </inertial>
    <dynamics damping="0.7" friction="1000.0"/>
  </link>
  <joint name="upper_left_arm_z_revolute" type="revolute">
    <axis xyz="0 0 1"/>
    <limit effort="1000.0" lower="-0.7" upper="0.7" velocity="5"/>
    <parent link="left_shoulder"/>
    <child link="upper_left_arm_z_revolute"/>
    <origin xyz="0 0 0"/>
  </joint>
  <link name="upper_left_arm_y_revolute">
    <collision>
      <geometry>
        <cylinder length="0.01" radius="0.01"/>
      </geometry>
    </collision>
    <inertial>
      <mass value="0.01"/>
      <inertia ixx="1.0" ixy="0.0" ixz="0.0" iyy="1.0" iyz="0.0" izz="1.0"/>
    </inertial>
    <origin xyz="0 0 0"/>
    <dynamics damping="0.7" friction="1000.0"/>
  </link>
  <joint name="upper_left_arm_y_revolute" type="revolute">
    <axis xyz="0 1 0"/>
    <limit effort="1000.0" lower="0" upper="0.4" velocity="5"/>
    <parent link="upper_left_arm_z_revolute"/>
    <child link="upper_left_arm_y_revolute"/>
    <origin xyz="0 0 0"/>
  </joint>
  <link name="upper_left_arm">
    <visual>
      <geometry>
        <box size="0.065 0.08 0.17"/>
      </geometry>
      <material name="grey"/>
    </visual>
    <collision>
      <geometry>
        <cylinder length="0.17" radius="0.046"/>
      </geometry>
    </collision>
    <inertial>
      <mass value="0.5"/>
      <inertia ixx="1.0" ixy="0.0" ixz="0.0" iyy="1.0" iyz="0.0" izz="1.0"/>
    </inertial>
    <dynamics damping="0.7" friction="1000.0"/>
  </link>
  <gazebo reference="upper_left_arm">
    <material>Gazebo/Gray</material>
  </gazebo>
  <joint name="shoulder_to_upper_left_arm" type="fixed">
    <parent link="upper_left_arm_y_revolute"/>
    <child link="upper_left_arm"/>
    <origin xyz="0 0 -0.17"/>
  </joint>
  <joint name="upper_to_lower_left_joint" type="revolute">
    <axis xyz="1 0 0"/>
    <limit effort="1000.0" lower="0" upper="1.5706" velocity="5"/>
    <parent link="upper_left_arm"/>
    <child link="lower_left_arm_y_revolute"/>
    <origin xyz="0 0 -.085"/>
  </joint>
  <link name="lower_left_arm_y_revolute">
    <collision>
      <geometry>
        <cylinder length="0.01" radius="0.01"/>
      </geometry>
    </collision>
    <inertial>
      <mass value="0.01"/>
      <inertia ixx="1.0" ixy="0.0" ixz="0.0" iyy="1.0" iyz="0.0" izz="1.0"/>
    </inertial>
    <origin xyz="0 0 0"/>
    <dynamics damping="0.7" friction="1000.0"/>
  </link>
  <joint name="lower_left_joint_to_lower_arm" type="fixed">
    <parent link="lower_left_arm_y_revolute"/>
    <child link="lower_left_arm"/>
    <origin xyz="0 0 -.105"/>
  </joint>
  <link name="lower_left_arm">
    <visual>
      <geometry>
        <box size="0.065 0.08 0.21"/>
      </geometry>
      <material name="grey"/>
    </visual>
    <collision>
      <geometry>
        <cylinder length="0.21" radius="0.046"/>
      </geometry>
    </collision>
    <inertial>
      <mass value="3"/>
      <inertia ixx="1.0" ixy="0.0" ixz="0.0" iyy="1.0" iyz="0.0" izz="1.0"/>
    </inertial>
    <dynamics damping="0.7" friction="1000.0"/>
  </link>
  <gazebo reference="lower_left_arm">
    <material>Gazebo/Gray</material>
  </gazebo>
  <link name="wrist_left_arm_z_revolute">
    <collision>
      <geometry>
        <cylinder length="0.01" radius="0.01"/>
      </geometry>
    </collision>
    <inertial>
      <mass value="0.01"/>
      <inertia ixx="1.0" ixy="0.0" ixz="0.0" iyy="1.0" iyz="0.0" izz="1.0"/>
    </inertial>
    <dynamics damping="0.7" friction="1000.0"/>
  </link>
  <joint name="wrist_left_arm_z_revolute" type="revolute">
    <axis xyz="0 0 1"/>
    <limit effort="1000.0" lower="-2" upper="2" velocity="5"/>
    <parent link="lower_left_arm"/>
    <child link="wrist_left_arm_z_revolute"/>
  </joint>
  <link name="wrist_left_arm_x_revolute">
    <collision>
      <geometry>
        <cylinder length="0.01" radius="0.01"/>
      </geometry>
    </collision>
    <inertial>
      <mass value="0.01"/>
      <inertia ixx="1.0" ixy="0.0" ixz="0.0" iyy="1.0" iyz="0.0" izz="1.0"/>
    </inertial>
    <dynamics damping="0.7" friction="1000.0"/>
  </link>
  <joint name="wrist_left_arm_x_revolute" type="fixed">
    <parent link="wrist_left_arm_z_revolute"/>
    <child link="wrist_left_arm_x_revolute"/>
  </joint>
  <link name="wrist_left_arm">
    <visual>
      <geometry>
        <sphere radius="0.0325"/>
      </geometry>
      <material name="black"/>
    </visual>
    <collision>
      <geometry>
        <cylinder length="0.075" radius="0.0375"/>
      </geometry>
    </collision>
    <inertial>
      <mass value="1"/>
      <inertia ixx="1.0" ixy="0.0" ixz="0.0" iyy="1.0" iyz="0.0" izz="1.0"/>
    </inertial>
    <dynamics damping="0.7" friction="1000.0"/>
  </link>
  <gazebo reference="wrist_left_arm">
    <material>Gazebo/Black</material>
  </gazebo>
  <joint name="lower_to_wrist_left_arm" type="revolute">
    <axis xyz="1 0 0"/>
    <limit effort="1000.0" lower="-1.047" upper="1.047" velocity="5"/>
    <parent link="wrist_left_arm_x_revolute"/>
    <child link="wrist_left_arm"/>
    <origin xyz="0 0 -0.105"/>
  </joint>
  <link name="finger1_left_arm">
    <visual>
      <geometry>
        <box size="0.01 0.01 0.05"/>
      </geometry>
      <origin xyz="0 0 -0.025"/>
      <material name="grey"/>
    </visual>
    <collision>
      <geometry>
        <cylinder length="0.05" radius="0.005"/>
      </geometry>
    </collision>
    <inertial>
      <mass value="0.2"/>
      <inertia ixx="1.0" ixy="0.0" ixz="0.0" iyy="1.0" iyz="0.0" izz="1.0"/>
    </inertial>
    <dynamics damping="0.7" friction="1000.0"/>
  </link>
  <gazebo reference="finger1_left_arm">
    <material>Gazebo/Gray</material>
  </gazebo>
  <joint name="wrist_to_finger1_left_arm" type="revolute">
    <axis xyz="0 1 0"/>
    <limit effort="1000.0" lower="0.68" upper="0" velocity="5"/>
    <parent link="wrist_left_arm"/>
    <child link="finger1_left_arm"/>
    <origin rpy="0 -0.3926875 0" xyz="0.01875 0 -0.0375"/>
  </joint>
  <link name="finger2_left_arm">
    <visual>
      <geometry>
        <box size="0.01 0.03 0.05"/>
      </geometry>
      <origin xyz="0 0 -0.025"/>
      <material name="grey"/>
    </visual>
    <collision>
      <geometry>
        <cylinder length="0.05" radius="0.005"/>
      </geometry>
    </collision>
    <inertial>
      <mass value="0.2"/>
      <inertia ixx="1.0" ixy="0.0" ixz="0.0" iyy="1.0" iyz="0.0" izz="1.0"/>
    </inertial>
    <dynamics damping="0.7" friction="1000.0"/>
  </link>
  <gazebo reference="finger2_left_arm">
    <material>Gazebo/Gray</material>
  </gazebo>
  <joint name="wrist_to_finger2_left_arm" type="revolute">
    <axis xyz="0 1 0"/>
    <limit effort="1000.0" lower="0" upper="-0.68" velocity="5"/>
    <parent link="wrist_left_arm"/>
    <child link="finger2_left_arm"/>
    <origin rpy="0 0.3926875 0" xyz="-0.01875 0 -0.0375"/>
  </joint>
  <!-- ................END LEFT ARM................. -->
  <!-- ................SENSORS...................... -->
  <link name="laser_base">
    <visual>
      <geometry>
        <box size="0.02 0.03 0.04"/>
      </geometry>
      <material name="blue">
        <color rgba="0 0 1 .9"/>
      </material>
    </visual>
    <collision>
      <geometry>
        <cylinder length="0.001" radius="0.0001"/>
      </geometry>
    </collision>  
    <inertial>
      <mass value=".001"/>
      <inertia ixx="1.0" ixy="0.0" ixz="0.0" iyy="1.0" iyz="0.0" izz="1.0"/>
    </inertial>
  </link>
  <joint name="laser_base_to_torso" type="fixed">
    <parent link="base_torso"/>
    <child link="laser_base"/>
    <origin rpy="1.5708 0 0" xyz="0.09 0 .06"/>
  </joint>
  <link name="laser_joint">
    <collision>
      <geometry>
        <cylinder length="0.005" radius="0.003"/>
      </geometry>
    </collision>
    <inertial>
      <mass value="0.01"/>
      <inertia ixx="1.0" ixy="0.0" ixz="0.0" iyy="1.0" iyz="0.0" izz="1.0"/>
    </inertial>
    <dynamics damping="0.7" friction="1000.0"/>
  </link>
  <joint name="laser_joint_to_base" type="revolute">
    <axis xyz="0 0 1"/>
    <limit effort="1000.0" lower="-.77" upper=".77" velocity="5"/>
    <parent link="laser_base"/>
    <child link="laser_joint"/>
    <origin rpy="0 0 0" xyz="0.025 0 0"/>
  </joint>
  <link name="laser_sensor">
    <visual>
      <geometry>
        <cylinder length="0.02" radius="0.03"/>
      </geometry>
      <material name="black">
        <color rgba="0 0 0 1"/>
      </material>
    </visual>
    <inertial>
      <mass value=".001"/>
      <inertia ixx="1.0" ixy="0.0" ixz="0.0" iyy="1.0" iyz="0.0" izz="1.0"/>
    </inertial>
  </link>
  <joint name="laser_sensor_to_joint" type="fixed">
    <parent link="laser_joint"/>
    <child link="laser_sensor"/>
    <origin rpy="0 1.5707 0" xyz="0 0 0"/>
  </joint>

  <!-- ................END SENSORS.................. -->
</robot>

